[ERROR] File already exists: /raid/local/containers/enroot-data/user-1787/pytorch
Loading checkpoint shards:   0%|          | 0/30 [00:00<?, ?it/s]Loading checkpoint shards:   3%|▎         | 1/30 [00:05<02:51,  5.91s/it]Loading checkpoint shards:   7%|▋         | 2/30 [00:19<04:43, 10.14s/it]Loading checkpoint shards:  10%|█         | 3/30 [00:26<03:57,  8.80s/it]Loading checkpoint shards:  13%|█▎        | 4/30 [00:27<02:31,  5.81s/it]Loading checkpoint shards:  17%|█▋        | 5/30 [00:28<01:41,  4.07s/it]Loading checkpoint shards:  20%|██        | 6/30 [00:29<01:11,  2.99s/it]Loading checkpoint shards:  23%|██▎       | 7/30 [00:40<02:12,  5.77s/it]Loading checkpoint shards:  27%|██▋       | 8/30 [00:41<01:34,  4.31s/it]Loading checkpoint shards:  30%|███       | 9/30 [00:43<01:10,  3.35s/it]Loading checkpoint shards:  33%|███▎      | 10/30 [00:44<00:53,  2.69s/it]Loading checkpoint shards:  37%|███▋      | 11/30 [00:45<00:42,  2.24s/it]Loading checkpoint shards:  40%|████      | 12/30 [00:46<00:34,  1.93s/it]Loading checkpoint shards:  43%|████▎     | 13/30 [00:48<00:29,  1.74s/it]Loading checkpoint shards:  47%|████▋     | 14/30 [00:49<00:25,  1.62s/it]Loading checkpoint shards:  50%|█████     | 15/30 [00:50<00:22,  1.50s/it]Loading checkpoint shards:  53%|█████▎    | 16/30 [00:51<00:19,  1.42s/it]Loading checkpoint shards:  57%|█████▋    | 17/30 [00:53<00:17,  1.36s/it]Loading checkpoint shards:  57%|█████▋    | 17/30 [00:53<00:41,  3.17s/it]
Traceback (most recent call last):
  File "/home/projects/fraudagent/hase-michael/V3/batch.py", line 64, in <module>
    main()
  File "/home/projects/fraudagent/hase-michael/V3/batch.py", line 61, in main
    process_chunk(chunks[gpu_index], model_name, gpu_index)
  File "/home/projects/fraudagent/hase-michael/V3/batch.py", line 8, in process_chunk
    model = AutoModelForCausalLM.from_pretrained(
  File "/usr/local/lib/python3.10/dist-packages/transformers/models/auto/auto_factory.py", line 571, in from_pretrained
    return model_class.from_pretrained(
  File "/usr/local/lib/python3.10/dist-packages/transformers/modeling_utils.py", line 279, in _wrapper
    return func(*args, **kwargs)
  File "/usr/local/lib/python3.10/dist-packages/transformers/modeling_utils.py", line 4399, in from_pretrained
    ) = cls._load_pretrained_model(
  File "/usr/local/lib/python3.10/dist-packages/transformers/modeling_utils.py", line 4833, in _load_pretrained_model
    disk_offload_index, cpu_offload_index = _load_state_dict_into_meta_model(
  File "/usr/local/lib/python3.10/dist-packages/torch/utils/_contextlib.py", line 116, in decorate_context
    return func(*args, **kwargs)
  File "/usr/local/lib/python3.10/dist-packages/transformers/modeling_utils.py", line 787, in _load_state_dict_into_meta_model
    param = param[...]
torch.OutOfMemoryError: CUDA out of memory. Tried to allocate 448.00 MiB. GPU 0 has a total capacity of 79.11 GiB of which 116.88 MiB is free. Including non-PyTorch memory, this process has 78.99 GiB memory in use. Of the allocated memory 78.46 GiB is allocated by PyTorch, and 24.48 MiB is reserved by PyTorch but unallocated. If reserved but unallocated memory is large try setting PYTORCH_CUDA_ALLOC_CONF=expandable_segments:True to avoid fragmentation.  See documentation for Memory Management  (https://pytorch.org/docs/stable/notes/cuda.html#environment-variables)
